Workbook

Sheet Planilha1
A1: SKU | B1: Preço Foco Considerando Rebate | F1: AMAZON | G1: ARMAZÉM PARAIBA | H1: B2W | I1: CAMICADO | J1: CARREFOUR | K1: VIA | L1: COLOMBO | M1: CYBELAR | N1: IMPÉRIO DOS MÓVEIS | O1: LEROY MERLIN | P1: LOJA MADESA | Q1: LOJAS MM | R1: MAGALU | S1: MELI PREMIUM | T1: MELI CLASSICO | U1: MELI FG BRASIL | V1: KOERICH | W1: RIACHUELO | X1: SICREDI | Y1: WHIRLPOOL | Z1: ZEMA | AA1: MELI SP ITAPEVI PREMIUM | AB1: MELI SP ITAPEVI CLÁSSICO | AC1: MELI PE PREMIUM | AD1: MELI PE CLÁSSICO | AE1: QUERO-QUERO | AF1: MADEIRA MADEIRA
A2: 044745ZXTLIB | B2: 519.98 | C2: 397.5884 | D2: =B2/C2-1 -> 0.30783494 | E2: =ROUNDUP(B2+10,-1)-0.01 -> 529.99 | F2: 529.99 | H2: 529.99 | I2: 529.99 | J2: 529.99 | L2: 529.99 | M2: 529.99 | O2: 529.99 | R2: 529.99 | W2: 529.99 | X2: 529.99 | Y2: 529.99 | Z2: 529.99 | AE2: 529.99 | AF2: =ROUNDUP(AE2+10,-1)-0.01 -> 539.99
A3: 044805ZXTFLH | B3: 879.96 | C3: 686.9943 | D3: =B3/C3-1 -> 0.28088399 | E3: =ROUNDUP(B3+10,-1)-0.01 -> 889.99 | F3: 889.99 | G3: 889.99 | H3: 889.99 | I3: 889.99 | J3: 889.99 | K3: 889.99 | L3: 889.99 | M3: 889.99 | N3: 889.99 | Q3: 889.99 | R3: 889.99 | W3: 889.99 | X3: 889.99 | Y3: 889.99 | Z3: 889.99 | AE3: 889.99 | AF3: =ROUNDUP(AE3+10,-1)-0.01 -> 899.99
A4: 044825ZXTFBM | B4: 729.96 | C4: 562.7779 | D4: =B4/C4-1 -> 0.29706586 | E4: =ROUNDUP(B4+10,-1)-0.01 -> 739.99 | F4: 739.99 | H4: 739.99 | I4: 739.99 | J4: 739.99 | K4: 739.99 | L4: 739.99 | M4: 739.99 | O4: 739.99 | P4: 739.9 | Q4: 739.99 | R4: 739.99 | X4: 739.99 | Y4: 739.99 | Z4: 739.99 | AE4: 739.99 | AF4: =ROUNDUP(AE4+10,-1)-0.01 -> 749.99
A5: 044825ZXTFLH | B5: 739.91 | C5: 562.7779 | D5: =B5/C5-1 -> 0.31474601 | E5: =ROUNDUP(B5+10,-1)-0.01 -> 749.99 | F5: 749.99 | H5: 749.99 | I5: 749.99 | J5: 749.99 | K5: 749.99 | L5: 749.99 | M5: 749.99 | O5: 749.99 | P5: 749.9 | Q5: 749.99 | R5: 749.99 | X5: 749.99 | Y5: 749.99 | Z5: 749.99 | AE5: 749.99 | AF5: =ROUNDUP(AE5+10,-1)-0.01 -> 759.99
A6: 044915ZXTPER | B6: 559.91 | C6: 427.7378 | D6: =B6/C6-1 -> 0.30900285 | E6: =ROUNDUP(B6+10,-1)-0.01 -> 569.99 | F6: 569.99 | H6: 569.99 | I6: 569.99 | J6: 569.99 | K6: 569.99 | L6: 569.99 | M6: 569.99 | O6: 569.99 | Q6: 569.99 | W6: 569.99 | X6: 569.99 | Y6: 569.99 | Z6: 569.99 | AE6: 569.99 | AF6: =ROUNDUP(AE6+10,-1)-0.01 -> 579.99
A7: 1060094RFCT | B7: 4539.97 | C7: 3743.2889 | D7: =B7/C7-1 -> 0.21282918 | E7: =ROUNDUP(B7+10,-1)-0.01 -> 4549.99 | F7: 4549.99 | G7: 4549.99 | H7: 4549.99 | I7: 4549.99 | K7: 4549.99 | L7: 4549.99 | M7: 4549.99 | N7: 4549.99 | P7: 4549.9 | Q7: 4549.99 | R7: 4549.99 | V7: 4549.99 | W7: 4549.99 | X7: 4549.99 | Y7: 4549.99 | Z7: 4549.99 | AA7: 4549.99 | AB7: 4549.99 | AC7: 4549.99 | AD7: 4549.99 | AE7: 4549.99 | AF7: =ROUNDUP(AE7+10,-1)-0.01 -> 4559.99
A8: 1082093E | B8: 1699.97 | C8: 1373.5417 | D8: =B8/C8-1 -> 0.23765445 | E8: =ROUNDUP(B8+10,-1)-0.01 -> 1709.99 | F8: 1719.99 | G8: 1719.99 | H8: 1719.99 | I8: 1719.99 | J8: 1719.99 | K8: 1719.99 | L8: 1719.99 | M8: 1719.99 | P8: 1719.9 | Q8: 1719.99 | R8: 1719.99 | V8: 1719.99 | W8: 1719.99 | X8: 1719.99 | Y8: 1719.99 | Z8: 1719.99 | AE8: 1719.99 | AF8: 1719.99
A9: 10935Z | B9: 799.96 | C9: 628.1343 | D9: =B9/C9-1 -> 0.2735493 | E9: =ROUNDUP(B9+10,-1)-0.01 -> 809.99 | F9: 819.99 | H9: 819.99 | I9: 819.99 | J9: 819.99 | K9: 819.99 | L9: 819.99 | M9: 819.99 | O9: 819.99 | P9: 819.9 | Q9: 819.99 | R9: 819.99 | S9: 819.99 | T9: 819.99 | V9: 819.99 | W9: 819.99 | X9: 819.99 | Y9: 819.99 | Z9: 819.99 | AE9: 819.99 | AF9: 819.99
A10: 10938N3E4G | B10: 1479.97 | C10: 1198.5095 | D10: =B10/C10-1 -> 0.23484211 | E10: =ROUNDUP(B10+10,-1)-0.01 -> 1489.99 | F10: 1489.99 | H10: 1489.99 | I10: 1489.99 | J10: 1489.99 | L10: 1489.99 | M10: 1489.99 | N10: 1489.99 | P10: 1489.9 | R10: 1489.99 | V10: 1489.99 | W10: 1489.99 | X10: 1489.99 | Y10: 1489.99 | Z10: 1489.99 | AE10: 1489.99 | AF10: =ROUNDUP(AE10+10,-1)-0.01 -> 1499.99
A11: 1094091ECP | B11: 839.91 | C11: 648.1358 | D11: =B11/C11-1 -> 0.29588583 | E11: =ROUNDUP(B11+10,-1)-0.01 -> 849.99 | F11: 849.99 | H11: 849.99 | I11: 849.99 | J11: 849.99 | L11: 849.99 | M11: 849.99 | P11: 849.9 | R11: 849.99 | V11: 849.99 | W11: 849.99 | X11: 849.99 | Y11: 849.99 | Z11: 849.99 | AE11: 849.99 | AF11: =ROUNDUP(AE11+10,-1)-0.01 -> 859.99
A12: 1094092E2G | B12: 1029.97 | C12: 831.7681 | D12: =B12/C12-1 -> 0.23828986 | E12: =ROUNDUP(B12+10,-1)-0.01 -> 1039.99 | F12: 1039.99 | H12: 1039.99 | I12: 1039.99 | J12: 1039.99 | L12: 1039.99 | M12: 1039.99 | P12: 1039.9 | V12: 1039.99 | W12: 1039.99 | X12: 1039.99 | Y12: 1039.99 | Z12: 1039.99 | AE12: 1039.99 | AF12: =ROUNDUP(AE12+10,-1)-0.01 -> 1049.99
A13: 10948N2E4G | B13: 1169.97 | C13: 922.0637 | D13: =B13/C13-1 -> 0.26886028 | E13: =ROUNDUP(B13+10,-1)-0.01 -> 1179.99 | F13: 1179.99 | G13: 1179.99 | H13: 1179.99 | I13: 1179.99 | J13: 1179.99 | K13: 1179.99 | L13: 1179.99 | M13: 1179.99 | N13: 1179.99 | O13: 1179.99 | P13: 1179.9 | Q13: 1179.99 | R13: 1179.99 | V13: 1179.99 | W13: 1179.99 | X13: 1179.99 | Y13: 1179.99 | Z13: 1179.99 | AE13: 1179.99 | AF13: =ROUNDUP(AE13+10,-1)-0.01 -> 1189.99
A14: 1097091E | B14: 979.91 | C14: 756.5254 | D14: =B14/C14-1 -> 0.29527707 | E14: =ROUNDUP(B14+10,-1)-0.01 -> 989.99 | F14: 989.99 | H14: 989.99 | I14: 989.99 | J14: 989.99 | K14: 989.99 | L14: 989.99 | M14: 989.99 | N14: 989.99 | P14: 989.9 | Q14: 989.99 | R14: 989.99 | T14: 989.99 | V14: 989.99 | W14: 989.99 | X14: 989.99 | Y14: 989.99 | Z14: 989.99 | AA14: 989.99 | AC14: 989.99 | AE14: 989.99 | AF14: =ROUNDUP(AE14+10,-1)-0.01 -> 999.99
A15: 10978N2E | B15: 1119.97 | C15: 876.0875 | D15: =B15/C15-1 -> 0.27837687 | E15: =ROUNDUP(B15+10,-1)-0.01 -> 1129.99 | F15: 1129.99 | G15: 1129.99 | H15: 1129.99 | I15: 1129.99 | J15: 1129.99 | K15: 1129.99 | L15: 1129.99 | M15: 1129.99 | N15: 1129.99 | O15: 1129.99 | P15: 1129.9 | Q15: 1129.99 | R15: 1129.99 | T15: 1129.99 | V15: 1129.99 | W15: 1129.99 | X15: 1129.99 | Y15: 1129.99 | Z15: 1129.99 | AA15: 1129.99 | AC15: 1129.99 | AE15: 1129.99 | AF15: =ROUNDUP(AE15+10,-1)-0.01 -> 1139.99
A16: 12487K | B16: 389.91 | C16: 294.4744 | D16: =B16/C16-1 -> 0.32408793 | E16: =ROUNDUP(B16+10,-1)-0.01 -> 399.99 | F16: 399.99 | G16: 399.99 | H16: 399.99 | J16: 399.99 | L16: 399.99 | P16: 399.9 | V16: 399.99 | W16: 399.99 | AA16: 399.99
A17: 16695Z2 | B17: 979.98 | C17: 725.2315 | D17: =B17/C17-1 -> 0.35126508 | E17: =ROUNDUP(B17+10,-1)-0.01 -> 989.99 | F17: 989.99 | H17: 989.99 | I17: 989.99 | K17: 989.99 | L17: 989.99 | M17: 989.99 | O17: 989.99 | P17: 989.9 | R17: 989.99 | S17: 989.99 | T17: 989.99 | V17: 989.99 | W17: 989.99 | X17: 989.99 | Y17: 989.99 | Z17: 989.99 | AE17: 989.99 | AF17: =ROUNDUP(AE17+10,-1)-0.01 -> 999.99
A18: 42545Z2TSIMK | B18: 449.98 | C18: 340.189 | D18: =B18/C18-1 -> 0.3227353 | E18: =ROUNDUP(B18+10,-1)-0.01 -> 459.99 | F18: 459.99 | G18: 459.99 | H18: 459.99 | I18: 459.99 | K18: 459.99 | L18: 459.99 | M18: 459.99 | N18: 459.99 | O18: 459.99 | P18: 459.9 | Q18: 459.99 | R18: 459.99 | S18: 459.99 | T18: 459.99 | W18: 459.99 | X18: 459.99 | Y18: 459.99 | Z18: 459.99 | AA18: 459.99 | AB18: 459.99 | AE18: 459.99
A19: 42555Z2TSIMK | B19: 369.98 | C19: 272.8706 | D19: =B19/C19-1 -> 0.35588077 | E19: =ROUNDUP(B19+10,-1)-0.01 -> 379.99 | H19: 379.99 | P19: 379.9
A20: 42805Z4XPE | B20: 379.91 | C20: 283.6616 | D20: =B20/C20-1 -> 0.33930712 | E20: =ROUNDUP(B20+10,-1)-0.01 -> 389.99 | L20: 389.99
A21: 42805Z4XPT | B21: 379.96 | C21: 283.6616 | D21: =B21/C21-1 -> 0.33948338 | E21: =ROUNDUP(B21+10,-1)-0.01 -> 389.99 | L21: 389.99
A22: 42905Z6XTFBM | B22: 499.98 | C22: 379.7124 | D22: =B22/C22-1 -> 0.3167334 | E22: =ROUNDUP(B22+10,-1)-0.01 -> 509.99 | F22: 519.99 | H22: 519.99 | I22: 519.99 | K22: 519.99 | L22: 519.99 | M22: 519.99 | N22: 519.99 | O22: 519.99 | P22: 519.9 | Q22: 519.99 | R22: 519.99 | S22: 519.99 | T22: 519.99 | W22: 519.99 | X22: 519.99 | Y22: 519.99 | Z22: 519.99 | AA22: 519.99 | AB22: 519.99
A23: 42905Z6XTLIB | B23: 499.98 | C23: 379.7124 | D23: =B23/C23-1 -> 0.3167334 | E23: =ROUNDUP(B23+10,-1)-0.01 -> 509.99 | F23: 519.99 | H23: 519.99 | I23: 519.99 | K23: 519.99 | L23: 519.99 | M23: 519.99 | N23: 519.99 | O23: 519.99 | P23: 519.9 | Q23: 519.99 | R23: 519.99 | S23: 519.99 | T23: 519.99 | W23: 519.99 | X23: 519.99 | Y23: 519.99 | Z23: 519.99 | AA23: 519.99 | AB23: 519.99
A24: 42905Z6XTPER | B24: 499.91 | C24: 379.7124 | D24: =B24/C24-1 -> 0.31654905 | E24: =ROUNDUP(B24+10,-1)-0.01 -> 509.99 | F24: 519.99 | H24: 519.99 | I24: 519.99 | K24: 519.99 | L24: 519.99 | M24: 519.99 | N24: 519.99 | O24: 519.99 | P24: 519.9 | Q24: 519.99 | R24: 519.99 | S24: 519.99 | T24: 519.99 | W24: 519.99 | X24: 519.99 | Y24: 519.99 | Z24: 519.99 | AA24: 519.99 | AB24: 519.99
A25: 42917G4XTPER | B25: 339.91 | C25: 257.2836 | D25: =B25/C25-1 -> 0.32114911 | E25: =ROUNDUP(B25+10,-1)-0.01 -> 349.99 | L25: 349.99
A26: 42917K6XTPT | B26: 499.96 | C26: 381.5436 | D26: =B26/C26-1 -> 0.31036138 | E26: =ROUNDUP(B26+10,-1)-0.01 -> 509.99 | F26: 519.99 | H26: 519.99 | I26: 519.99 | K26: 519.99 | L26: 519.99 | M26: 519.99 | N26: 519.99 | O26: 519.99 | P26: 519.9 | Q26: 519.99 | R26: 519.99 | S26: 519.99 | T26: 519.99 | W26: 519.99 | X26: 519.99 | Y26: 519.99 | Z26: 519.99 | AA26: 519.99 | AB26: 519.99
A27: GCGM40900109 | B27: 2679.97 | C27: 2179.1389 | D27: =B27/C27-1 -> 0.22982982 | E27: =ROUNDUP(B27+10,-1)-0.01 -> 2689.99 | F27: 2689.99 | H27: 2689.99 | I27: 2689.99 | J27: 2689.99 | K27: 2689.99 | M27: 2689.99 | N27: 2689.99 | P27: 2689.9 | R27: 2689.99 | S27: 2689.99 | T27: 2689.99 | W27: 2689.99 | X27: 2689.99 | Y27: 2689.99 | Z27: 2689.99 | AE27: 2689.99
A28: GRAG270003F9 | B28: 2169.97 | C28: 1700.9232 | D28: =B28/C28-1 -> 0.27576013 | E28: =ROUNDUP(B28+10,-1)-0.01 -> 2179.99 | F28: 2179.99 | H28: 2179.99 | I28: 2179.99 | J28: 2179.99 | K28: 2179.99 | L28: 2179.99 | M28: 2179.99 | N28: 2179.99 | P28: 2179.9 | Q28: 2179.99 | R28: 2179.99 | S28: 2179.99 | T28: 2179.99 | W28: 2179.99 | X28: 2179.99 | Y28: 2179.99 | Z28: 2179.99 | AE28: 2179.99
A29: GREM1370037K | B29: 879.96 | C29: 687.9753 | D29: =B29/C29-1 -> 0.27905755 | E29: =ROUNDUP(B29+10,-1)-0.01 -> 889.99 | F29: 889.99 | G29: 889.99 | H29: 889.99 | I29: 889.99 | J29: 889.99 | K29: 889.99 | L29: 889.99 | M29: 889.99 | N29: 889.99 | P29: 889.9 | Q29: 889.99 | R29: 889.99 | S29: 889.99 | T29: 889.99 | W29: 889.99 | X29: 889.99 | Y29: 889.99 | Z29: 889.99 | AA29: 889.99 | AC29: 889.99 | AD29: 889.99 | AE29: 889.99
A30: GREM2930037K | B30: 1499.91 | C30: 1204.7552 | D30: =B30/C30-1 -> 0.24499151 | E30: =ROUNDUP(B30+10,-1)-0.01 -> 1509.99 | F30: 1519.99 | H30: 1519.99 | I30: 1519.99 | J30: 1519.99 | K30: 1519.99 | L30: 1519.99 | M30: 1519.99 | N30: 1519.99 | Q30: 1519.99 | R30: 1519.99 | S30: 1519.99 | T30: 1519.99 | U30: 1519.99 | W30: 1519.99 | X30: 1519.99 | Y30: 1519.99 | Z30: 1519.99 | AE30: 1519.99
A31: GRNC1200013B | B31: 809.91 | C31: 627.2841 | D31: =B31/C31-1 -> 0.29113746 | E31: =ROUNDUP(B31+10,-1)-0.01 -> 819.99 | F31: 819.99 | G31: 819.99 | H31: 819.99 | I31: 819.99 | J31: 819.99 | K31: 819.99 | L31: 819.99 | M31: 819.99 | N31: 819.99 | O31: 819.99 | P31: 819.9 | Q31: 819.99 | S31: 819.99 | T31: 819.99 | U31: 819.99 | W31: 819.99 | X31: 819.99 | Y31: 819.99
A32: GRNC2400043B | B32: 1399.97 | C32: 1116.6396 | D32: =B32/C32-1 -> 0.25373487 | E32: =ROUNDUP(B32+10,-1)-0.01 -> 1409.99 | J32: 1419.99 | S32: 1419.99 | T32: 1419.99
A33: GRNC2400053B | B33: 1399.96 | C33: 1122.5365 | D33: =B33/C33-1 -> 0.24713985 | E33: =ROUNDUP(B33+10,-1)-0.01 -> 1409.99 | J33: 1419.99 | L33: 1419.99 | S33: 1419.99 | T33: 1419.99 | W33: 1419.99 | Z33: 1419.99
A34: GRNC2600133B | B34: 1479.97 | C34: 1200.635 | D34: =B34/C34-1 -> 0.23265605 | E34: =ROUNDUP(B34+10,-1)-0.01 -> 1489.99 | J34: 1489.99 | L34: 1489.99 | S34: 1489.99 | T34: 1489.99
A35: GRNC3000093B | B35: 1859.97 | C35: 1478.7812 | D35: =B35/C35-1 -> 0.25777228 | E35: =ROUNDUP(B35+10,-1)-0.01 -> 1869.99 | J35: 1869.99 | S35: 1869.99 | T35: 1869.99 | Z35: 1869.99
A36: GRRM25000109 | B36: 1599.96 | C36: 1295.5958 | D36: =B36/C36-1 -> 0.23492219 | E36: =ROUNDUP(B36+10,-1)-0.01 -> 1609.99 | F36: 1619.99 | H36: 1619.99 | I36: 1619.99 | J36: 1619.99 | K36: 1619.99 | L36: 1619.99 | M36: 1619.99 | P36: 1619.9 | R36: 1619.99 | T36: 1619.99 | W36: 1619.99 | X36: 1619.99 | Y36: 1619.99 | Z36: 1619.99 | AE36: 1619.99
A37: MDJA0200015ZPER | B37: 369.96 | C37: 283.2474 | D37: =B37/C37-1 -> 0.30613732 | E37: =ROUNDUP(B37+10,-1)-0.01 -> 379.99 | W37: 379.99
A38: MDJA0200015ZPT | B38: 369.96 | C38: 283.2474 | D38: =B38/C38-1 -> 0.30613732 | E38: =ROUNDUP(B38+10,-1)-0.01 -> 379.99 | W38: 379.99
A39: MDJA0400505ZPT | B39: 619.96 | C39: 494.642 | D39: =B39/C39-1 -> 0.25335091 | E39: =ROUNDUP(B39+10,-1)-0.01 -> 629.99 | F39: 629.99 | H39: 629.99 | I39: 629.99 | J39: 629.99 | K39: 629.99 | L39: 629.99 | M39: 629.99 | Q39: 629.99 | R39: 629.99 | W39: 629.99 | X39: 629.99 | Y39: 629.99 | Z39: 629.99 | AE39: 629.99 | AF39: =ROUNDUP(AE39+10,-1)-0.01 -> 639.99
A40: MDJA0400885ZFBM | B40: 519.98 | C40: 397.5884 | D40: =B40/C40-1 -> 0.30783494 | E40: =ROUNDUP(B40+10,-1)-0.01 -> 529.99 | F40: 529.99 | H40: 529.99 | I40: 529.99 | J40: 529.99 | K40: 529.99 | L40: 529.99 | M40: 529.99 | O40: 529.99 | Q40: 529.99 | R40: 529.99 | W40: 529.99 | X40: 529.99 | Y40: 529.99 | Z40: 529.99 | AE40: 529.99 | AF40: =ROUNDUP(AE40+10,-1)-0.01 -> 539.99
...

Sheet VIA
A1: Cód. Madesa | B1: Link | C1: Descrição | E1: 45964
A2: MDMU01000349 | B2: https://www.casasbahia.com.br/armario-gabinete-para-banheiro-80cm-2-portas-branco-madesa-branco/p/1564878896?utm_medium=Cpc&utm_source=google_freelisting&IdSku=1564878896&idLojista=11121&tipoLojista=3P&srsltid=AfmBOop_Bp4rltAP2-gQwn484FHi69XwNGSxAObZCtMIGeFTtP0MEbLHkVM | C2: Armário Gabinete para Banheiro 80cm 2 Portas Branco Madesa | D2: NEGOCIAÇÃO | E2: A prazo | F2: A vista | H2: Frete | I2: Prazo | J2: Comissão
A3: MDFC0100096E | B3: https://www.casasbahia.com.br/escrivaninha-em-l-mesa-para-computador-gamer-3-gavetas-branco-rustic-lisboa-madesa/p/1571532198?utm_source=google_freelisting&utm_medium=Cpc | C3: Escrivaninha Em L Mesa Para Computador Gamer 3 Gavetas Branco/Rustic Lisboa Madesa | D3: WEB - VIA | E3: 479.96 | F3: 422.36 | G3: =((E3-F3)/E3) -> 0.12001 | H3: 49.9 | I3: 7 | J3: =IF(SUMIFS(Negociados!C:C,Negociados!B:B,E3,Negociados!A:A,A2,Negociados!D:D,"<="&$E$1,Negociados!E:E,">="&$E$1),SUMIFS(Negociados!C:C,Negociados!B:B,E3,Negociados!A:A,A2,Negociados!D:D,"<="&$E$1,Negociados!E:E,">="&$E$1),19%) -> 0.08
A4: GRGT2350027K | B4: https://www.casasbahia.com.br/armario-cozinha-compacta-235cm-rustic-preto-gourmet-02/p/1569919017?utm_source=google_freelisting&utm_medium=Cpc | C4: Armário de Cozinha Compacta 235cm Rustic/Preto Gourmet Madesa 02 | D4: WEB - VIA | E4: 679.96 | F4: 598.36 | G4: =((E4-F4)/E4) -> 0.12000706 | H4: 49.9 | I4: 7 | J4: =IF(SUMIFS(Negociados!C:C,Negociados!B:B,E4,Negociados!A:A,A3,Negociados!D:D,"<="&$E$1,Negociados!E:E,">="&$E$1),SUMIFS(Negociados!C:C,Negociados!B:B,E4,Negociados!A:A,A3,Negociados!D:D,"<="&$E$1,Negociados!E:E,">="&$E$1),19%) -> 0.19
A5: GREM2610027K | B5: https://www.casasbahia.com.br/armario-de-cozinha-completa-261cm-rustic-preto/p/1566169964?utm_source=google_freelisting&utm_medium=Cpc | C5: Armário de Cozinha Completa 261cm Rustic/Preto Emilly Madesa 02 | D5: WEB - VIA | E5: 679.96 | F5: 598.36 | G5: =((E5-F5)/E5) -> 0.12000706 | H5: 49.9 | I5: 7 | J5: =IF(SUMIFS(Negociados!C:C,Negociados!B:B,E5,Negociados!A:A,A4,Negociados!D:D,"<="&$E$1,Negociados!E:E,">="&$E$1),SUMIFS(Negociados!C:C,Negociados!B:B,E5,Negociados!A:A,A4,Negociados!D:D,"<="&$E$1,Negociados!E:E,">="&$E$1),19%) -> 0.19
A6: MDJA0401827KOXF | B6: https://www.casasbahia.com.br/conjunto-sala-de-jantar-mesa-tampo-de-vidro-4-cadeiras-rustic-preto/p/1567001547?utm_medium=Cpc&utm_source=google_freelisting&IdSku=1567001547&idLojista=11121&tipoLojista=3P&srsltid=AfmBOorlC1bYaDRK5uDza005nDBC8uI21-dmMoH71swN94p7EgNiSBKBw3k | C6: Conjunto Sala de Jantar Mesa Tampo de Vidro 4 Cadeiras Rustic/Preto Oxford Evelin Madesa Rustic/Preto/Oxford | D6: WEB - VIA | E6: 379.96 | F6: 334.36 | G6: =((E6-F6)/E6) -> 0.12001263 | H6: 39.9 | I6: 7 | J6: =IF(SUMIFS(Negociados!C:C,Negociados!B:B,E6,Negociados!A:A,A5,Negociados!D:D,"<="&$E$1,Negociados!E:E,">="&$E$1),SUMIFS(Negociados!C:C,Negociados!B:B,E6,Negociados!A:A,A5,Negociados!D:D,"<="&$E$1,Negociados!E:E,">="&$E$1),19%) -> 0.19
A7: 10936E1E | B7: https://www.casasbahia.com.br/guarda-roupa-casal-monaco-3-portas-correr-1-espelho-madesa/p/1572081299?utm_medium=Cpc&utm_source=google_freelisting&IdSku=1572081299&idLojista=11121&tipoLojista=3P&srsltid=AfmBOor3erSrcNCT6mk07zEjot-tuu2pyS8r2ao50DmqZaz4tkVeHFUXdTI | C7: Guarda Roupa Casal Madesa Mônaco 3 Portas de Correr com Espelho - Rustic/Branco | D7: WEB - VIA | E7: 379.96 | F7: 334.36 | G7: =((E7-F7)/E7) -> 0.12001263 | H7: 39.9 | I7: 7 | J7: =IF(SUMIFS(Negociados!C:C,Negociados!B:B,E7,Negociados!A:A,A6,Negociados!D:D,"<="&$E$1,Negociados!E:E,">="&$E$1),SUMIFS(Negociados!C:C,Negociados!B:B,E7,Negociados!A:A,A6,Negociados!D:D,"<="&$E$1,Negociados!E:E,">="&$E$1),19%) -> 0.19
A8: MDJA0400027KPT | B8: https://www.casasbahia.com.br/mesa-tampo-de-madeira-com-4-cadeiras-rustic-preto/p/1526215299 | C8: Conjunto Sala de Jantar Madesa Cali Mesa Tampo de Madeira com 4 Cadeiras - Rustic/Preto/SintPreto | D8: WEB - VIA | E8: 699.96 | F8: 615.96 | G8: =((E8-F8)/E8) -> 0.12000686 | H8: 49.9 | I8: 7 | J8: =IF(SUMIFS(Negociados!C:C,Negociados!B:B,E8,Negociados!A:A,A7,Negociados!D:D,"<="&$E$1,Negociados!E:E,">="&$E$1),SUMIFS(Negociados!C:C,Negociados!B:B,E8,Negociados!A:A,A7,Negociados!D:D,"<="&$E$1,Negociados!E:E,">="&$E$1),19%) -> 0.19
A9: GREM32500209 | B9: https://www.casasbahia.com.br/armario-de-cozinha-completa-325cm-branco-emilly-madesa-02/p/1571928014 | C9: Armário de Cozinha Completa 325cm Branco Emilly Madesa 02 | D9: WEB - VIA | E9: 699.96 | F9: 615.96 | G9: =((E9-F9)/E9) -> 0.12000686 | H9: 49.9 | I9: 7 | J9: =IF(SUMIFS(Negociados!C:C,Negociados!B:B,E9,Negociados!A:A,A8,Negociados!D:D,"<="&$E$1,Negociados!E:E,">="&$E$1),SUMIFS(Negociados!C:C,Negociados!B:B,E9,Negociados!A:A,A8,Negociados!D:D,"<="&$E$1,Negociados!E:E,">="&$E$1),19%) -> 0.17
A10: MDJA0600437GPER | B10: https://www.casasbahia.com.br/sala-de-jantar-ohana-mesa-tampo-de-madeira-6-cadeiras-madesa-1501278613/p/1501278613?utm_medium=Cpc&utm_source=google_freelisting&IdSku=1501278613&idLojista=11121&tipoLojista=3P&srsltid=AfmBOopJx5Hbs_f_qT77tGBgdxH1eif7fW1vm6ERd7Zbocyt_8c1mHt-RjI | C10: Conjunto Sala de Jantar Madesa Ohana Mesa Tampo de Madeira com 6 Cadeiras - Rustic/Crema/Pérola Rustic/Crema/Pérola | D10: WEB - VIA | E10: 699.96 | F10: 615.96 | G10: =((E10-F10)/E10) -> 0.12000686 | H10: 49.9 | I10: 8 | J10: =IF(SUMIFS(Negociados!C:C,Negociados!B:B,E10,Negociados!A:A,A9,Negociados!D:D,"<="&$E$1,Negociados!E:E,">="&$E$1),SUMIFS(Negociados!C:C,Negociados!B:B,E10,Negociados!A:A,A9,Negociados!D:D,"<="&$E$1,Negociados!E:E,">="&$E$1),19%) -> 0.19
A11: 044805ZXTFLH | B11: https://www.casasbahia.com.br/sala-de-jantar-megan-mesa-tampo-de-madeira-6-cadeiras-madesa/p/1501279445 | C11: Conjunto Sala de Jantar Madesa Megan Mesa Tampo de Madeira com 6 Cadeiras - Rustic/Hibiscos | D11: WEB - VIA | E11: 889.96 | F11: 783.16 | G11: =((E11-F11)/E11) -> 0.12000539 | H11: 49.9 | I11: 7 | J11: =IF(SUMIFS(Negociados!C:C,Negociados!B:B,E11,Negociados!A:A,A10,Negociados!D:D,"<="&$E$1,Negociados!E:E,">="&$E$1),SUMIFS(Negociados!C:C,Negociados!B:B,E11,Negociados!A:A,A10,Negociados!D:D,"<="&$E$1,Negociados!E:E,">="&$E$1),19%) -> 0.19
A12: 044825ZXTFBM | B12: https://www.casasbahia.com.br/sala-de-jantar-maris-mesa-tampo-de-madeira-6-cadeiras-madesa-1501351993/p/1501351993?utm_medium=Cpc&utm_source=google_freelisting&IdSku=1501351993&idLojista=11121&tipoLojista=3P&srsltid=AfmBOooWk1Lo9Bg22Wcgo-peZ3Fxf_QpC0DEarIv399IJe-3a1g__wU3hxg | C12: Conjunto Sala de Jantar Madesa Maris Mesa Tampo de Madeira com 6 Cadeiras Rustic/Bege Marrom | D12: WEB - VIA | E12: 499.96 | F12: 439.96 | G12: =((E12-F12)/E12) -> 0.1200096 | H12: 39.9 | I12: 7 | J12: =IF(SUMIFS(Negociados!C:C,Negociados!B:B,E12,Negociados!A:A,A11,Negociados!D:D,"<="&$E$1,Negociados!E:E,">="&$E$1),SUMIFS(Negociados!C:C,Negociados!B:B,E12,Negociados!A:A,A11,Negociados!D:D,"<="&$E$1,Negociados!E:E,">="&$E$1),19%) -> 0.19
A13: 044825ZXTFLH | B13: https://www.casasbahia.com.br/sala-de-jantar-maris-mesa-tampo-de-madeira-6-cadeiras-madesa-1501279499/p/1501279499?utm_medium=Cpc&utm_source=google_freelisting&IdSku=1501279499&idLojista=11121&tipoLojista=3P&srsltid=AfmBOor7bz7ZJI833QTJiZKIuZuToWWJzO0mAcNobRD2UkJSJTs1gQa9iUw | C13: Conjunto Sala de Jantar Madesa Maris Mesa Tampo de Madeira com 6 Cadeiras - Rustic/Hibiscos Rustic/Floral Hibiscos | D13: WEB - VIA | E13: 399.96 | F13: 351.96 | G13: =((E13-F13)/E13) -> 0.120012 | H13: 39.9 | I13: 7 | J13: =IF(SUMIFS(Negociados!C:C,Negociados!B:B,E13,Negociados!A:A,A12,Negociados!D:D,"<="&$E$1,Negociados!E:E,">="&$E$1),SUMIFS(Negociados!C:C,Negociados!B:B,E13,Negociados!A:A,A12,Negociados!D:D,"<="&$E$1,Negociados!E:E,">="&$E$1),19%) -> 0.19
A14: MDJA0200015ZPER | B14: https://www.casasbahia.com.br/sala-de-jantar-gabi-mesa-tampo-de-madeira-2-cadeiras-madesa/p/1501458337 | C14: Conjunto Sala de Jantar Madesa Gabi Mesa Tampo de Madeira com 2 Cadeiras Rustic/Crema/Sintético Bege | D14: WEB - VIA | E14: 359.96 | F14: 316.76 | G14: =((E14-F14)/E14) -> 0.12001333 | H14: 39.99 | I14: 10 | J14: =IF(SUMIFS(Negociados!C:C,Negociados!B:B,E14,Negociados!A:A,A13,Negociados!D:D,"<="&$E$1,Negociados!E:E,">="&$E$1),SUMIFS(Negociados!C:C,Negociados!B:B,E14,Negociados!A:A,A13,Negociados!D:D,"<="&$E$1,Negociados!E:E,">="&$E$1),19%) -> 0.19
A15: MDJA0200015ZPT | B15: https://www.casasbahia.com.br/sala-de-jantar-gabi-mesa-tampo-de-madeira-2-cadeiras-madesa/p/1501279511 | C15: Conjunto Sala de Jantar Madesa Gabi Mesa Tampo de Madeira com 2 Cadeiras - Rustic/Preto/Sintético Preto Rustic/Preto/Sintético Preto | D15: WEB - VIA | E15: 339.96 | F15: 299.16 | G15: =((E15-F15)/E15) -> 0.12001412 | H15: 39.9 | I15: 7 | J15: =IF(SUMIFS(Negociados!C:C,Negociados!B:B,E15,Negociados!A:A,A14,Negociados!D:D,"<="&$E$1,Negociados!E:E,">="&$E$1),SUMIFS(Negociados!C:C,Negociados!B:B,E15,Negociados!A:A,A14,Negociados!D:D,"<="&$E$1,Negociados!E:E,">="&$E$1),19%) -> 0.19
A16: MDJA0400345ZPT | B16: https://www.casasbahia.com.br/sala-de-jantar-anita-mesa-tampo-de-vidro-4-cadeiras-madesa/p/1501269493 | C16: Conjunto Sala de Jantar Madesa Anita Mesa Tampo de Vidro com 4 Cadeiras - Rustic/Preto/Sintético Preto | D16: WEB - VIA | E16: 829.96 | F16: 730.36 | G16: =((E16-F16)/E16) -> 0.12000578 | H16: Grátis | I16: 7 | J16: =IF(SUMIFS(Negociados!C:C,Negociados!B:B,E16,Negociados!A:A,A15,Negociados!D:D,"<="&$E$1,Negociados!E:E,">="&$E$1),SUMIFS(Negociados!C:C,Negociados!B:B,E16,Negociados!A:A,A15,Negociados!D:D,"<="&$E$1,Negociados!E:E,">="&$E$1),19%) -> 0.19
A17: 045667GX4TFBM | B17: https://www.casasbahia.com.br/moveis/saladejantar/mesasecadeirasdejantar/kit-cintia-begemesa-tampo-de-madeira-4-cadeiras-madesa-1501005323.html?idsku=1501005323 | C17: Conjunto Sala de Jantar Madesa Cíntia Mesa Tampo de Madeira com 4 Cadeiras Rustic/Crema/Bege Marrom | D17: WEB - VIA | E17: 799.96 | F17: 703.96 | G17: =((E17-F17)/E17) -> 0.120006 | H17: Grátis | I17: 7 | J17: =IF(SUMIFS(Negociados!C:C,Negociados!B:B,E17,Negociados!A:A,A16,Negociados!D:D,"<="&$E$1,Negociados!E:E,">="&$E$1),SUMIFS(Negociados!C:C,Negociados!B:B,E17,Negociados!A:A,A16,Negociados!D:D,"<="&$E$1,Negociados!E:E,">="&$E$1),19%) -> 0.19
A18: MDJA0600177KPT | B18: https://www.casasbahia.com.br/mesa-tampo-de-madeira-com-6-cadeiras-rustic-preto/p/1526289961 | C18: Conjunto Sala de Jantar Madesa Medelin Mesa Tampo de Madeira com 6 Cadeiras - Rustic/Preto/SintPreto Rustic/Preto/Sint Preto | D18: WEB - VIA | E18: 1759.96 | F18: 1548.76 | G18: =((E18-F18)/E18) -> 0.12000273 | H18: Grátis | I18: 7 | J18: =IF(SUMIFS(Negociados!C:C,Negociados!B:B,E18,Negociados!A:A,A17,Negociados!D:D,"<="&$E$1,Negociados!E:E,">="&$E$1),SUMIFS(Negociados!C:C,Negociados!B:B,E18,Negociados!A:A,A17,Negociados!D:D,"<="&$E$1,Negociados!E:E,">="&$E$1),19%) -> 0.19
A19: MDJA0600177GBE | B19: https://www.casasbahia.com.br/mesa-tampo-de-madeira-com-6-cadeiras-rustic-crema-bege-rustic-1526211812/p/1526211812?utm_medium=Cpc&utm_source=google_freelisting&IdSku=1526211812&idLojista=11121&tipoLojista=3P&srsltid=AfmBOoojKpBxR9Z9Fc0ynJSW5RqgegYNUOeq9jOwLNJNOwJcGKtCE5-auSw | C19: Conjunto Sala de Jantar Madesa Medelin Mesa Tampo de Madeira com 6 Cadeiras - Rustic/Crema/Bege Rustic/Crema/Sint Bege | D19: WEB - VIA | E19: 1169.96 | F19: 1029.56 | G19: =((E19-F19)/E19) -> 0.1200041 | H19: Grátis | I19: 7 | J19: =IF(SUMIFS(Negociados!C:C,Negociados!B:B,E19,Negociados!A:A,A18,Negociados!D:D,"<="&$E$1,Negociados!E:E,">="&$E$1),SUMIFS(Negociados!C:C,Negociados!B:B,E19,Negociados!A:A,A18,Negociados!D:D,"<="&$E$1,Negociados!E:E,">="&$E$1),19%) -> 0.19
A20: MDJA060017D8PT | B20: https://www.casasbahia.com.br/mesa-tampo-de-madeira-com-6-cadeiras-preto-rustic-preto/p/1526289474 | C20: Conjunto Sala de Jantar Madesa Medelin Mesa Tampo de Madeira com 6 Cadeiras - Preto/Rustic/SintPreto Preto/Rustic/Sint Preto | D20: WEB - VIA | E20: 539.96 | F20: 539.96 | G20: =((E20-F20)/E20) -> 0 | H20: 39.9 | I20: 7 | J20: =IF(SUMIFS(Negociados!C:C,Negociados!B:B,E20,Negociados!A:A,A19,Negociados!D:D,"<="&$E$1,Negociados!E:E,">="&$E$1),SUMIFS(Negociados!C:C,Negociados!B:B,E20,Negociados!A:A,A19,Negociados!D:D,"<="&$E$1,Negociados!E:E,">="&$E$1),19%) -> 0.19
A21: MDJA0601417KPT | B21: https://www.casasbahia.com.br/kit-sala-de-jantar-mesa-6-cadeiras-preto-augusta/p/1562516892 | C21: Conjunto Sala de Jantar Mesa Tampo de Madeira 6 Cadeiras Preto/Rustic Augusta Madesa | D21: WEB - VIA | E21: 554.99 | F21: 488.39 | G21: =((E21-F21)/E21) -> 0.12000216 | H21: 39.9 | I21: 7 | J21: =IF(SUMIFS(Negociados!C:C,Negociados!B:B,E21,Negociados!A:A,A20,Negociados!D:D,"<="&$E$1,Negociados!E:E,">="&$E$1),SUMIFS(Negociados!C:C,Negociados!B:B,E21,Negociados!A:A,A20,Negociados!D:D,"<="&$E$1,Negociados!E:E,">="&$E$1),19%) -> 0.19
A22: 42917K6XTPT | B22: https://www.casasbahia.com.br/kit-6-cadeiras-rustic-preto-madesa-4291/p/1500994267 | C22: Kit 6 Cadeiras de Jantar 4291 Madesa Rustic/Preto Rustic/Preto | D22: WEB - VIA | E22: 1669.96 | F22: 1469.56 | G22: =((E22-F22)/E22) -> 0.12000287 | H22: Grátis | I22: 10 | J22: =IF(SUMIFS(Negociados!C:C,Negociados!B:B,E22,Negociados!A:A,A21,Negociados!D:D,"<="&$E$1,Negociados!E:E,">="&$E$1),SUMIFS(Negociados!C:C,Negociados!B:B,E22,Negociados!A:A,A21,Negociados!D:D,"<="&$E$1,Negociados!E:E,">="&$E$1),19%) -> 0.19
A23: 42805Z4XPT | B23: https://www.casasbahia.com.br/kit-4-cadeiras-rustic-preto-madesa/p/1501992427 | C23: Kit 4 Cadeiras de Jantar 4280 Madesa Rustic/Preto Rustic/Preto | D23: WEB - VIA | E23: 1119.96 | F23: 985.56 | G23: =((E23-F23)/E23) -> 0.12000429 | H23: 59.9 | I23: 7 | J23: =IF(SUMIFS(Negociados!C:C,Negociados!B:B,E23,Negociados!A:A,A22,Negociados!D:D,"<="&$E$1,Negociados!E:E,">="&$E$1),SUMIFS(Negociados!C:C,Negociados!B:B,E23,Negociados!A:A,A22,Negociados!D:D,"<="&$E$1,Negociados!E:E,">="&$E$1),19%) -> 0.19
A24: 42917G4XTPER | B24: https://www.casasbahia.com.br/kit-4-cadeiras-perola-madesa-4291/p/1500994468 | C24: Kit 4 Cadeiras de Jantar 4291 Madesa Rustic/Crema/Pérola Rustic/Crema/Pérola | D24: WEB - VIA | E24: 499.96 | F24: 439.96 | G24: =((E24-F24)/E24) -> 0.1200096 | H24: 39.9 | I24: 7 | J24: =IF(SUMIFS(Negociados!C:C,Negociados!B:B,E24,Negociados!A:A,A23,Negociados!D:D,"<="&$E$1,Negociados!E:E,">="&$E$1),SUMIFS(Negociados!C:C,Negociados!B:B,E24,Negociados!A:A,A23,Negociados!D:D,"<="&$E$1,Negociados!E:E,">="&$E$1),19%) -> 0.19
A25: 42805Z4XPE | B25: https://www.casasbahia.com.br/kit-4-cadeiras-em-mdf-e-mdp-madesa/p/1501992396 | C25: Kit 4 Cadeiras 4280 Madesa Rustic/Crema/Sintético Bege | D25: WEB - VIA | E25: 559.96 | F25: 492.76 | G25: =((E25-F25)/E25) -> 0.12000857 | H25: 49.9 | I25: 7 | J25: =IF(SUMIFS(Negociados!C:C,Negociados!B:B,E25,Negociados!A:A,A24,Negociados!D:D,"<="&$E$1,Negociados!E:E,">="&$E$1),SUMIFS(Negociados!C:C,Negociados!B:B,E25,Negociados!A:A,A24,Negociados!D:D,"<="&$E$1,Negociados!E:E,">="&$E$1),19%) -> 0.19
A26: 42905Z4XTPT | B26: https://www.casasbahia.com.br/kit-4-cadeiras-4290-madesa-rustic-preto/p/1516415812 | C26: Kit 4 Cadeiras 4290 Madesa - Rustic/Preto Rustic/Preto | D26: WEB - VIA | E26: 469.96 | F26: 413.56 | G26: =((E26-F26)/E26) -> 0.12001021 | H26: 39.9 | I26: 7 | J26: =IF(SUMIFS(Negociados!C:C,Negociados!B:B,E26,Negociados!A:A,A25,Negociados!D:D,"<="&$E$1,Negociados!E:E,">="&$E$1),SUMIFS(Negociados!C:C,Negociados!B:B,E26,Negociados!A:A,A25,Negociados!D:D,"<="&$E$1,Negociados!E:E,">="&$E$1),19%) -> 0.19
A27: 1094091ECP | B27: https://www.casasbahia.com.br/guarda-roupa-solteiro-madesa-denver-2-portas-de-correr-com-espelho-com-pes/p/1501022927 | C27: Guarda-Roupa Solteiro Madesa Denver 2 Portas de Correr com Espelho com Pés Branco | D27: WEB - VIA | E27: - | F27: - | G27: =((E27-F27)/E27) -> #VALUE! | H27: - | I27: - | J27: =IF(SUMIFS(Negociados!C:C,Negociados!B:B,E27,Negociados!A:A,A26,Negociados!D:D,"<="&$E$1,Negociados!E:E,">="&$E$1),SUMIFS(Negociados!C:C,Negociados!B:B,E27,Negociados!A:A,A26,Negociados!D:D,"<="&$E$1,Negociados!E:E,">="&$E$1),19%) -> 0.19
A28: 10935Z | B28: https://www.casasbahia.com.br/guarda-roupa-casal-monaco-3-portas-de-correr-15426026/p/15426026?utm_medium=Cpc&utm_source=google_freelisting&IdSku=15426026&idLojista=11121&tipoLojista=3P&srsltid=AfmBOoqGvKMyMrg8xbGmz-iCL-UXZYCwNiAMCL7CXrQjpQFaoGPau6HHIZo | C28: Guarda-Roupa Casal Madesa Mônaco 3 Portas de Correr Rustic | D28: WEB - VIA | E28: 749.96 | F28: 659.96 | G28: =((E28-F28)/E28) -> 0.1200064 | H28: Grátis | I28: 7 | J28: =IF(SUMIFS(Negociados!C:C,Negociados!B:B,E28,Negociados!A:A,A27,Negociados!D:D,"<="&$E$1,Negociados!E:E,">="&$E$1),SUMIFS(Negociados!C:C,Negociados!B:B,E28,Negociados!A:A,A27,Negociados!D:D,"<="&$E$1,Negociados!E:E,">="&$E$1),19%) -> 0.19
A29: 106309 | B29: https://www.casasbahia.com.br/guarda-roupa-casal-100-mdf-royale-3-portas-de-correr/p/14252194 | C29: Guarda Roupa Casal 100% MDF Madesa Royale 3 Portas de Correr - Branco Branco | D29: WEB - VIA | E29: 1449.96 | F29: 1275.96 | G29: =((E29-F29)/E29) -> 0.12000331 | H29: Grátis | I29: 7 | J29: =IF(SUMIFS(Negociados!C:C,Negociados!B:B,E29,Negociados!A:A,A28,Negociados!D:D,"<="&$E$1,Negociados!E:E,">="&$E$1),SUMIFS(Negociados!C:C,Negociados!B:B,E29,Negociados!A:A,A28,Negociados!D:D,"<="&$E$1,Negociados!E:E,">="&$E$1),19%) -> 0.19
A30: GREM1370037K | B30: https://www.casasbahia.com.br/cozinha-madesa-armario-balcao-e-paneleiro-rustic-preto-1504288903/p/1504288903?utm_medium=comparadorpreco&utm_source=zoom&utm_content=1504288903&pid=zoom_int&c=zoomCPA&cm_mmc=zoom_XML-_-MOVE-_-Comparador-_-1504288903&idLojista=11121&tipoLojista=3P&utm_campaign=56f3b8423c5d4904b04d42fe12c5b9fb | C30: Armário de Cozinha Compacta 137cm Rustic/Preto Emilly Gold Madesa 03 | D30: WEB - VIA | E30: 899.96 | F30: 791.96 | G30: =((E30-F30)/E30) -> 0.12000533 | H30: Grátis | I30: 7 | J30: =IF(SUMIFS(Negociados!C:C,Negociados!B:B,E30,Negociados!A:A,A29,Negociados!D:D,"<="&$E$1,Negociados!E:E,">="&$E$1),SUMIFS(Negociados!C:C,Negociados!B:B,E30,Negociados!A:A,A29,Negociados!D:D,"<="&$E$1,Negociados!E:E,">="&$E$1),19%) -> 0.19
A31: GRRM25000109 | B31: https://www.casasbahia.com.br/cozinha-completa-reims-com-armario-e-balcao-branco-madesa/p/1505749224 | C31: Cozinha Completa Madesa Reims 250001 com Armário e Balcão - Branco | D31: WEB - VIA | E31: 1489.96 | F31: 1311.16 | G31: =((E31-F31)/E31) -> 0.12000322 | H31: Grátis | I31: 7 | J31: =IF(SUMIFS(Negociados!C:C,Negociados!B:B,E31,Negociados!A:A,A30,Negociados!D:D,"<="&$E$1,Negociados!E:E,">="&$E$1),SUMIFS(Negociados!C:C,Negociados!B:B,E31,Negociados!A:A,A30,Negociados!D:D,"<="&$E$1,Negociados!E:E,">="&$E$1),19%) -> 0.19
A32: GRRM240001D8 | B32: https://www.casasbahia.com.br/cozinha-completa-madesa-reims-240001-com-armario-e-balcao-preto-rustic/p/1502903701 | C32: Armário de Cozinha Completa 240cm Preto/Rustic Reims Madesa 01 | D32: WEB - VIA | E32: 1489.96 | F32: 1311.16 | G32: =((E32-F32)/E32) -> 0.12000322 | H32: Grátis | I32: 7 | J32: =IF(SUMIFS(Negociados!C:C,Negociados!B:B,E32,Negociados!A:A,A31,Negociados!D:D,"<="&$E$1,Negociados!E:E,">="&$E$1),SUMIFS(Negociados!C:C,Negociados!B:B,E32,Negociados!A:A,A31,Negociados!D:D,"<="&$E$1,Negociados!E:E,">="&$E$1),19%) -> 0.19
A33: GRSM170001A9 | B33: https://www.casasbahia.com.br/cozinha-compacta-100-mdf-madesa-smart-170-cm-modulada-com-armario-balcao-e-tampo/p/1502903658 | C33: Cozinha Compacta 100% MDF Madesa Smart 170 cm Modulada Com Armário, Balcão e Tampo Branco/Rustic/Crema | D33: WEB - VIA | E33: 1199.96 | F33: 1055.96 | G33: =((E33-F33)/E33) -> 0.120004 | H33: Grátis | I33: 7 | J33: =IF(SUMIFS(Negociados!C:C,Negociados!B:B,E33,Negociados!A:A,A32,Negociados!D:D,"<="&$E$1,Negociados!E:E,">="&$E$1),SUMIFS(Negociados!C:C,Negociados!B:B,E33,Negociados!A:A,A32,Negociados!D:D,"<="&$E$1,Negociados!E:E,">="&$E$1),19%) -> 0.19
A34: 044915ZXTPER | B34: https://www.casasbahia.com.br/conjunto-sala-jantar-mesa-tampo-madeira-4-cadeiras-madesa-1500994674/p/1500994674?utm_medium=Cpc&utm_source=google_freelisting&IdSku=1500994674&idLojista=11121&tipoLojista=3P&srsltid=AfmBOopSNphyra9CH9l085GrSVlnGWhAx1sJEAxno3FAdt_FTuz7xWWwDdc | C34: Conjunto Sala de Jantar Madesa Rute Mesa Tampo de Madeira com 4 Cadeiras - Rustic/Pérola Rustic/Pérola | D34: WEB - VIA | E34: 1199.96 | F34: 1055.96 | G34: =((E34-F34)/E34) -> 0.120004 | H34: Grátis | I34: 10 | J34: =IF(SUMIFS(Negociados!C:C,Negociados!B:B,E34,Negociados!A:A,A33,Negociados!D:D,"<="&$E$1,Negociados!E:E,">="&$E$1),SUMIFS(Negociados!C:C,Negociados!B:B,E34,Negociados!A:A,A33,Negociados!D:D,"<="&$E$1,Negociados!E:E,">="&$E$1),19%) -> 0.19
A35: MDJA0601346ESIL | B35: https://www.casasbahia.com.br/conjunto-sala-de-jantar-mesa-tampo-de-vidro-6-cadeiras/p/1547659626 | C35: Conjunto Sala de Jantar Mesa Tampo de Vidro 6 Cadeiras Rustic/Branco/Silver Geórgia Madesa | D35: WEB - VIA | E35: 399.96 | F35: 351.96 | G35: =((E35-F35)/E35) -> 0.120012 | H35: 39.9 | I35: 7 | J35: =IF(SUMIFS(Negociados!C:C,Negociados!B:B,E35,Negociados!A:A,A34,Negociados!D:D,"<="&$E$1,Negociados!E:E,">="&$E$1),SUMIFS(Negociados!C:C,Negociados!B:B,E35,Negociados!A:A,A34,Negociados!D:D,"<="&$E$1,Negociados!E:E,">="&$E$1),19%) -> 0.19
A36: MDJA0800047KPT | B36: https://www.casasbahia.com.br/conjunto-sala-de-jantar-mesa-tampo-de-madeira-8-cadeiras-rustic-preto-marisa-madesa-rustic-preto/p/1559194853 | C36: Conjunto Sala de Jantar Mesa Tampo de Madeira 8 Cadeiras Rustic/Preto Marisa Madesa | D36: WEB - VIA | E36: 539.96 | F36: 475.16 | G36: =((E36-F36)/E36) -> 0.12000889 | H36: 39.9 | I36: 7 | J36: =IF(SUMIFS(Negociados!C:C,Negociados!B:B,E36,Negociados!A:A,A35,Negociados!D:D,"<="&$E$1,Negociados!E:E,">="&$E$1),SUMIFS(Negociados!C:C,Negociados!B:B,E36,Negociados!A:A,A35,Negociados!D:D,"<="&$E$1,Negociados!E:E,">="&$E$1),19%) -> 0.19
A37: MDJA060135F9SIL | B37: https://www.casasbahia.com.br/conjunto-sala-de-jantar-mesa-tampo-de-madeira-6-cadeiras/p/1547659415 | C37: Conjunto Sala de Jantar Mesa Tampo de Madeira 6 Cadeiras Rustic/Cinza/Silver Hanna Madesa | D37: WEB - VIA | E37: 1399.96 | F37: 1231.96 | G37: =((E37-F37)/E37) -> 0.12000343 | H37: Grátis | I37: 10 | J37: =IF(SUMIFS(Negociados!C:C,Negociados!B:B,E37,Negociados!A:A,A36,Negociados!D:D,"<="&$E$1,Negociados!E:E,">="&$E$1),SUMIFS(Negociados!C:C,Negociados!B:B,E37,Negociados!A:A,A36,Negociados!D:D,"<="&$E$1,Negociados!E:E,">="&$E$1),19%) -> 0.19
A38: MDJA0401617KPT | B38: https://www.casasbahia.com.br/conjunto-sala-de-jantar-mesa-tampo-de-madeira-4-cadeiras-rustic-preto-claire-madesa-rustic-preto/p/1562867516 | C38: Conjunto Sala de Jantar Mesa Tampo de Madeira 4 Cadeiras Rustic/Preto Claire Madesa Rustic/Preto | D38: WEB - VIA | E38: 649.96 | F38: 571.96 | G38: =((E38-F38)/E38) -> 0.12000739 | H38: Grátis | I38: 7 | J38: =IF(SUMIFS(Negociados!C:C,Negociados!B:B,E38,Negociados!A:A,A37,Negociados!D:D,"<="&$E$1,Negociados!E:E,">="&$E$1),SUMIFS(Negociados!C:C,Negociados!B:B,E38,Negociados!A:A,A37,Negociados!D:D,"<="&$E$1,Negociados!E:E,">="&$E$1),19%) -> 0.19
A39: MDJA040157F9FLH | B39: https://www.casasbahia.com.br/conjunto-sala-de-jantar-mesa-tampo-de-madeira-4-cadeiras/p/1561846995 | C39: Conjunto Sala de Jantar Mesa Tampo de Madeira 4 Cadeiras Rustic/Cinza/Floral Hibiscos Samara Madesa Rustic/Cinza/Hibiscos | D39: WEB - VIA | E39: 1199.96 | F39: 1055.96 | G39: =((E39-F39)/E39) -> 0.120004 | H39: Grátis | I39: 7 | J39: =IF(SUMIFS(Negociados!C:C,Negociados!B:B,E39,Negociados!A:A,A38,Negociados!D:D,"<="&$E$1,Negociados!E:E,">="&$E$1),SUMIFS(Negociados!C:C,Negociados!B:B,E39,Negociados!A:A,A38,Negociados!D:D,"<="&$E$1,Negociados!E:E,">="&$E$1),19%) -> 0.19
A40: MDJA0400505ZPT | B40: https://www.casasbahia.com.br/conjunto-sala-de-jantar-maya-mesa-4-cadeiras-madesa-1501988611/p/1501988611?utm_medium=Cpc&utm_source=google_freelisting&IdSku=1501988611&idLojista=11121&tipoLojista=3P&srsltid=AfmBOooiQj7zjpNsD6e5LWPqVPs2W4LQN6RF0mOCqXVidLU2xHT4TxUSHMw | C40: Conjunto Sala de Jantar Madesa Maya Mesa Tampo de Vidro com 4 Cadeiras - Rustic/Sintético Preto Rustic/Sintético Preto | D40: WEB - VIA | E40: 779.96 | F40: 686.36 | G40: =((E40-F40)/E40) -> 0.12000615 | H40: Grátis | I40: 7 | J40: =IF(SUMIFS(Negociados!C:C,Negociados!B:B,E40,Negociados!A:A,A39,Negociados!D:D,"<="&$E$1,Negociados!E:E,">="&$E$1),SUMIFS(Negociados!C:C,Negociados!B:B,E40,Negociados!A:A,A39,Negociados!D:D,"<="&$E$1,Negociados!E:E,">="&$E$1),19%) -> 0.19
...

Sheet MADEIRA
A1: Cód. Madesa | B1: LINK | C1: Descrição | D1: NEGOCIAÇÃO | E1: 45950
A2: GRTE2900015Z9B | B2: https://www.madeiramadeira.com.br/cozinha-completa-madesa-stella-290001-com-armario-e-balcao-rustic-branco-rustic-cor-rustic-branco-ru-382167574.html?index=prod-poc-madeira | C2: Cozinha Completa Madesa Stella 290001 com Armário e Balcão | D2: WEB - MADEIRA | E2: Preço | F2: FRETE | G2: PRAZO | H2: Comissão
A3: 044915ZXTFLH | B3: https://www.madeiramadeira.com.br/conjunto-sala-de-jantar-madesa-rute-mesa-tampo-de-madeira-com-4-cadeiras-rustic-floral-hibiscos-cor-886371540.html?index=prod-poc-madeira | C3: Conjunto Sala de Jantar Madesa Rute Mesa Tampo de Madeira com 4 Cadeiras - Rustic/Hibiscos | D3: WEB - MADEIRA | E3: 359.97 | F3: 39.9 | G3: 7 | H3: =IF(SUMIFS(Negociados!C:C,Negociados!B:B,E3,Negociados!A:A,A2,Negociados!D:D,"<="&$E$1,Negociados!E:E,">="&$E$1),SUMIFS(Negociados!C:C,Negociados!B:B,E3,Negociados!A:A,A2,Negociados!D:D,"<="&$E$1,Negociados!E:E,">="&$E$1),19%) -> 0.19
A4: MDFC0100096E | B4: https://www.madeiramadeira.com.br/escrivaninha-em-l-mesa-para-computador-gamer-3-gavetas-branco-rustic-lisboa-madesa-912735258.html?index=prod-poc-madeira | C4: Escrivaninha Em L Mesa Para Computador Gamer 3 Gavetas Branco/Rustic Lisboa Madesa | D4: WEB - MADEIRA | E4: 359.97 | F4: 39.9 | G4: 7 | H4: =IF(SUMIFS(Negociados!C:C,Negociados!B:B,E4,Negociados!A:A,A3,Negociados!D:D,"<="&$E$1,Negociados!E:E,">="&$E$1),SUMIFS(Negociados!C:C,Negociados!B:B,E4,Negociados!A:A,A3,Negociados!D:D,"<="&$E$1,Negociados!E:E,">="&$E$1),19%) -> 0.19
A5: MDMU01000349 | B5: https://www.madeiramadeira.com.br/armario-gabinete-para-banheiro-80cm-2-portas-branco-madesa-305784556.html?index=prod-poc-madeira | C5: Armário Gabinete para Banheiro 80cm 2 Portas Branco Madesa | D5: WEB - MADEIRA | E5: - | F5: - | G5: - | H5: =IF(SUMIFS(Negociados!C:C,Negociados!B:B,E5,Negociados!A:A,A4,Negociados!D:D,"<="&$E$1,Negociados!E:E,">="&$E$1),SUMIFS(Negociados!C:C,Negociados!B:B,E5,Negociados!A:A,A4,Negociados!D:D,"<="&$E$1,Negociados!E:E,">="&$E$1),19%) -> 0.19
A6: 1082091ECP | B6: https://www.madeiramadeira.com.br/guarda-roupa-casal-madesa-napoli-3-portas-de-correr-central-com-espelho-com-pes-branco-cor-branco-326146969.html?index=prod-poc-madeira | C6: Guarda-Roupa Casal Madesa Napoli 3 Portas de Correr Central com Espelho com Pés - Branco | D6: WEB - MADEIRA | E6: 449.97 | F6: 39.9 | G6: 7 | H6: =IF(SUMIFS(Negociados!C:C,Negociados!B:B,E6,Negociados!A:A,A5,Negociados!D:D,"<="&$E$1,Negociados!E:E,">="&$E$1),SUMIFS(Negociados!C:C,Negociados!B:B,E6,Negociados!A:A,A5,Negociados!D:D,"<="&$E$1,Negociados!E:E,">="&$E$1),19%) -> 0.19
A7: 1094092E2G | B7: https://www.madeiramadeira.com.br/guarda-roupa-solteiro-madesa-dallas-2-portas-de-correr-de-espelho-2-gavetas-branco-cor-branco-160696536.html?index=prod-poc-madeira | C7: Guarda-Roupa Solteiro Madesa Dallas 2 Portas de Correr de Espelho 2 Gavetas Branco | D7: WEB - MADEIRA | E7: 649.99 | F7: 49.9 | G7: 7 | H7: =IF(SUMIFS(Negociados!C:C,Negociados!B:B,E7,Negociados!A:A,A6,Negociados!D:D,"<="&$E$1,Negociados!E:E,">="&$E$1),SUMIFS(Negociados!C:C,Negociados!B:B,E7,Negociados!A:A,A6,Negociados!D:D,"<="&$E$1,Negociados!E:E,">="&$E$1),19%) -> 0.19
A8: MDJA040139F9SIL | B8: https://www.madeiramadeira.com.br/conj-mesa-tampo-de-madeira-4-cadeiras-rustic-cinza-silver-714572884.html | C8: Conjunto Sala de Jantar Mesa Tampo de Madeira 4 Cadeiras Rustic/Cinza/Silver Karina Madesa Rustic/Cinza/Silver | D8: WEB - MADEIRA | E8: 839.99 | F8: 49.9 | G8: 7 | H8: =IF(SUMIFS(Negociados!C:C,Negociados!B:B,E8,Negociados!A:A,A7,Negociados!D:D,"<="&$E$1,Negociados!E:E,">="&$E$1),SUMIFS(Negociados!C:C,Negociados!B:B,E8,Negociados!A:A,A7,Negociados!D:D,"<="&$E$1,Negociados!E:E,">="&$E$1),19%) -> 0.19
A9: 1094F8 | B9: https://www.madeiramadeira.com.br/guarda-roupa-solteiro-2-portas-branco-cinza-905565679.html?index=prod-poc-madeira | C9: Guarda-Roupa Solteiro Madesa Denver 2 Portas de Correr Branco/Cinza | D9: WEB - MADEIRA | E9: 759.97 | F9: Grátis | G9: 7 | H9: =IF(SUMIFS(Negociados!C:C,Negociados!B:B,E9,Negociados!A:A,A8,Negociados!D:D,"<="&$E$1,Negociados!E:E,">="&$E$1),SUMIFS(Negociados!C:C,Negociados!B:B,E9,Negociados!A:A,A8,Negociados!D:D,"<="&$E$1,Negociados!E:E,">="&$E$1),19%) -> 0.19
A10: 60245Z5ZPP | B10: https://www.madeiramadeira.com.br/rack-madesa-dubai-para-tv-ate-65-polegadas-com-pes-rustic-cor-rustic-276383392.html?index=prod-poc-madeira | C10: Rack Madesa Dubai para TV até 65 Polegadas com Pés - Rustic Rustic | D10: WEB - MADEIRA | E10: 939.99 | F10: Grátis | G10: 7 | H10: =IF(SUMIFS(Negociados!C:C,Negociados!B:B,E10,Negociados!A:A,A9,Negociados!D:D,"<="&$E$1,Negociados!E:E,">="&$E$1),SUMIFS(Negociados!C:C,Negociados!B:B,E10,Negociados!A:A,A9,Negociados!D:D,"<="&$E$1,Negociados!E:E,">="&$E$1),19%) -> 0.19
A11: MDJA0401827KOXF | B11: https://www.madeiramadeira.com.br/conjunto-sala-de-jantar-mesa-tampo-de-vidro-4-cadeiras-rustic-preto-oxford-evelin-madesa-rustic-381198735.html | C11: Conjunto Sala de Jantar Mesa Tampo de Vidro 4 Cadeiras Rustic/Preto Oxford Evelin Madesa Rustic/Preto/Oxford | D11: WEB - MADEIRA | E11: 879.97 | F11: Grátis | G11: 10 | H11: =IF(SUMIFS(Negociados!C:C,Negociados!B:B,E11,Negociados!A:A,A10,Negociados!D:D,"<="&$E$1,Negociados!E:E,">="&$E$1),SUMIFS(Negociados!C:C,Negociados!B:B,E11,Negociados!A:A,A10,Negociados!D:D,"<="&$E$1,Negociados!E:E,">="&$E$1),19%) -> 0.19
A12: 10936E1E | B12: https://www.madeiramadeira.com.br/guarda-roupa-casal-madesa-monaco-3-portas-de-correr-com-espelho-rustic-branco-cor-rustic-branco-896640340.html | C12: Guarda Roupa Casal Madesa Mônaco 3 Portas de Correr com Espelho - Rustic/Branco | D12: WEB - MADEIRA | E12: 1019.99 | F12: Grátis | G12: 7 | H12: =IF(SUMIFS(Negociados!C:C,Negociados!B:B,E12,Negociados!A:A,A11,Negociados!D:D,"<="&$E$1,Negociados!E:E,">="&$E$1),SUMIFS(Negociados!C:C,Negociados!B:B,E12,Negociados!A:A,A11,Negociados!D:D,"<="&$E$1,Negociados!E:E,">="&$E$1),19%) -> 0.19
A13: 6024095ZPP | B13: https://www.madeiramadeira.com.br/rack-madesa-dubai-para-tv-ate-65-polegadas-com-pes-branco-rustic-095z-cor-branco-rustic-246706764.html | C13: Rack Madesa Dubai para TV até 65 Polegadas com Pés - Branco/Rustic | D13: WEB - MADEIRA | E13: 899.97 | F13: Grátis | G13: 7 | H13: =IF(SUMIFS(Negociados!C:C,Negociados!B:B,E13,Negociados!A:A,A12,Negociados!D:D,"<="&$E$1,Negociados!E:E,">="&$E$1),SUMIFS(Negociados!C:C,Negociados!B:B,E13,Negociados!A:A,A12,Negociados!D:D,"<="&$E$1,Negociados!E:E,">="&$E$1),19%) -> 0.19
A14: 1097091E | B14: https://www.madeiramadeira.com.br/guarda-roupa-solteiro-madesa-tokio-2-portas-de-correr-com-espelho-2-gavetas-branco-cor-branco-301003051.html?index=vr-prod-poc-madeira-listings-best-seller-desc&seller=17012 | C14: Guarda-Roupa Solteiro Madesa Tokio 2 Portas de Correr com Espelho 2 Gavetas Branco | D14: WEB - MADEIRA | E14: 1439.97 | F14: Grátis | G14: 7 | H14: =IF(SUMIFS(Negociados!C:C,Negociados!B:B,E14,Negociados!A:A,A13,Negociados!D:D,"<="&$E$1,Negociados!E:E,">="&$E$1),SUMIFS(Negociados!C:C,Negociados!B:B,E14,Negociados!A:A,A13,Negociados!D:D,"<="&$E$1,Negociados!E:E,">="&$E$1),19%) -> 0.19
A15: 10948N2E4G | B15: https://www.madeiramadeira.com.br/guarda-roupa-solteiro-madesa-dallas-plus-2-portas-de-correr-de-espelho-4-gavetas-preto-cor-preto-235441141.html | C15: Guarda-Roupa Solteiro Madesa Dallas Plus 2 Portas de Correr de Espelho 4 Gavetas | D15: WEB - MADEIRA | E15: 1439.97 | F15: Grátis | G15: 7 | H15: =IF(SUMIFS(Negociados!C:C,Negociados!B:B,E15,Negociados!A:A,A14,Negociados!D:D,"<="&$E$1,Negociados!E:E,">="&$E$1),SUMIFS(Negociados!C:C,Negociados!B:B,E15,Negociados!A:A,A14,Negociados!D:D,"<="&$E$1,Negociados!E:E,">="&$E$1),19%) -> 0.19
A16: 1085093E | B16: https://www.madeiramadeira.com.br/guarda-roupa-casal-madesa-veneza-3-portas-de-correr-com-espelho-branco-cor-branco-570039174.html?index=vr-prod-poc-madeira-listings-best-seller-desc&seller=17012 | C16: Guarda-Roupa Casal Madesa Veneza 3 Portas de Correr de Espelhos - Branco Branco | D16: WEB - MADEIRA | E16: 1439.97 | F16: Grátis | G16: 7 | H16: =IF(SUMIFS(Negociados!C:C,Negociados!B:B,E16,Negociados!A:A,A15,Negociados!D:D,"<="&$E$1,Negociados!E:E,">="&$E$1),SUMIFS(Negociados!C:C,Negociados!B:B,E16,Negociados!A:A,A15,Negociados!D:D,"<="&$E$1,Negociados!E:E,">="&$E$1),19%) -> 0.19
A17: GRRM320002D8 | B17: https://www.madeiramadeira.com.br/cozinha-completa-madesa-reims-320002-com-armario-e-balcao-preto-cor-preto-156353621.html | C17: Cozinha Completa Madesa Reims 320002 com Armário e Balcão - Preto | D17: WEB - MADEIRA | E17: 1999.99 | F17: Grátis | G17: 7 | H17: =IF(SUMIFS(Negociados!C:C,Negociados!B:B,E17,Negociados!A:A,A16,Negociados!D:D,"<="&$E$1,Negociados!E:E,">="&$E$1),SUMIFS(Negociados!C:C,Negociados!B:B,E17,Negociados!A:A,A16,Negociados!D:D,"<="&$E$1,Negociados!E:E,">="&$E$1),19%) -> 0.19
A18: GRAG1800027K | B18: https://www.madeiramadeira.com.br/cozinha-completa-madesa-agata-180002-com-armario-e-balcao-sem-tampo-e-pia-rustic-preto-442209207.html?index=vr-prod-poc-madeira-listings-best-seller-desc&seller=17012 | C18: Armário de Cozinha Compacta 180cm Rustic Preto Agata Madesa 02 | D18: WEB - MADEIRA | E18: 1889.97 | F18: Grátis | G18: 7 | H18: =IF(SUMIFS(Negociados!C:C,Negociados!B:B,E18,Negociados!A:A,A17,Negociados!D:D,"<="&$E$1,Negociados!E:E,">="&$E$1),SUMIFS(Negociados!C:C,Negociados!B:B,E18,Negociados!A:A,A17,Negociados!D:D,"<="&$E$1,Negociados!E:E,">="&$E$1),19%) -> 0.19
A19: GRAG270003F9 | B19: https://www.madeiramadeira.com.br/cozinha-completa-270003-com-armario-e-balcao-rustic-cinza-947252637.html?index=vr-prod-poc-madeira-listings-best-seller-desc&seller=17012 | C19: Cozinha Completa Madesa Agata 270003 com Armário e Balcão (Sem Tampo e Pia) - Rustic/Cinza Rustic/Cinza | D19: WEB - MADEIRA | E19: 1689.97 | F19: Grátis | G19: 10 | H19: =IF(SUMIFS(Negociados!C:C,Negociados!B:B,E19,Negociados!A:A,A18,Negociados!D:D,"<="&$E$1,Negociados!E:E,">="&$E$1),SUMIFS(Negociados!C:C,Negociados!B:B,E19,Negociados!A:A,A18,Negociados!D:D,"<="&$E$1,Negociados!E:E,">="&$E$1),19%) -> 0.19
A20: GRGM27000709 | B20: https://www.madeiramadeira.com.br/cozinha-completa-100-mdf-madesa-acordes-270007-com-armario-e-balcao-frentes-branco-brilho-cor-branc-134523242.html | C20: Cozinha Completa 100% MDF Madesa Acordes 270007 com Armário e Balcão - Frentes Branco Brilho Branco | D20: WEB - MADEIRA | E20: 1979.97 | F20: Grátis | G20: 7 | H20: =IF(SUMIFS(Negociados!C:C,Negociados!B:B,E20,Negociados!A:A,A19,Negociados!D:D,"<="&$E$1,Negociados!E:E,">="&$E$1),SUMIFS(Negociados!C:C,Negociados!B:B,E20,Negociados!A:A,A19,Negociados!D:D,"<="&$E$1,Negociados!E:E,">="&$E$1),19%) -> 0.19
... A22: MDJA0401377GSIM | B22: https://www.madeiramadeira.com.br/conjunto-sala-de-jantar-mesa-tampo-de-madeira-4-cadeiras-ru-187574777.html | C22: Conjunto Sala de Jantar Mesa Tampo de Madeira 4 Cadeiras Rustic/Crema/Imperial Livia Madesa Rustic/Crema/Imperial | D22: WEB - MADEIRA | E22: 879.97 | F22: Grátis | G22: 10 | H22: =IF(SUMIFS(Negociados!C:C,Negociados!B:B,E22,Negociados!A:A,A21,Negociados!D:D,"<="&$E$1,Negociados!E:E,">="&$E$1),SUMIFS(Negociados!C:C,Negociados!B:B,E22,Negociados!A:A,A21,Negociados!D:D,"<="&$E$1,Negociados!E:E,">="&$E$1),19%) -> 0.19
A23: 044915ZXTPER | B23: https://www.madeiramadeira.com.br/conjunto-sala-de-jantar-madesa-rute-mesa-tampo-de-madeira-com-4-cadeiras-rustic-perola-cor-rustic-pe-200453321.html | C23: Conjunto Sala de Jantar Madesa Rute Mesa Tampo de Madeira com 4 Cadeiras Rustic/Sintético Bege | D23: WEB - MADEIRA | E23: 449.97 | F23: 39.9 | G23: 7 | H23: =IF(SUMIFS(Negociados!C:C,Negociados!B:B,E23,Negociados!A:A,A22,Negociados!D:D,"<="&$E$1,Negociados!E:E,">="&$E$1),SUMIFS(Negociados!C:C,Negociados!B:B,E23,Negociados!A:A,A22,Negociados!D:D,"<="&$E$1,Negociados!E:E,">="&$E$1),19%) -> 0.19
A24: MDJA0400505ZPT | B24: https://www.madeiramadeira.com.br/conjunto-sala-de-jantar-madesa-maya-mesa-tampo-de-vidro-com-4-cadeiras-rustic-sintetico-preto-cor-ru-277315967.html | C24: Conjunto Sala de Jantar Madesa Maya Mesa Tampo de Vidro com 4 Cadeiras Rustic/Sintético Preto | D24: WEB - MADEIRA | E24: 566.99 | F24: 39.9 | G24: 7 | H24: =IF(SUMIFS(Negociados!C:C,Negociados!B:B,E24,Negociados!A:A,A23,Negociados!D:D,"<="&$E$1,Negociados!E:E,">="&$E$1),SUMIFS(Negociados!C:C,Negociados!B:B,E24,Negociados!A:A,A23,Negociados!D:D,"<="&$E$1,Negociados!E:E,">="&$E$1),19%) -> 0.19
A25: 044825ZXTFLH | B25: https://www.madeiramadeira.com.br/conjunto-sala-de-jantar-madesa-maris-mesa-tampo-de-madeira-com-6-cadeiras-rustic-floral-hibiscos-cor-189720810.html | C25: Conjunto Sala de Jantar Madesa Maris Mesa Tampo de Madeira com 6 Cadeiras Rustic/Floral Hibiscos | D25: WEB - MADEIRA | E25: 519.97 | F25: 39.9 | G25: 7 | H25: =IF(SUMIFS(Negociados!C:C,Negociados!B:B,E25,Negociados!A:A,A24,Negociados!D:D,"<="&$E$1,Negociados!E:E,">="&$E$1),SUMIFS(Negociados!C:C,Negociados!B:B,E25,Negociados!A:A,A24,Negociados!D:D,"<="&$E$1,Negociados!E:E,">="&$E$1),19%) -> 0.19
A26: MDJA0400885ZPER | B26: https://www.madeiramadeira.com.br/conjunto-sala-de-jantar-madesa-luana-mesa-tampo-de-madeira-com-4-cadeiras-rustic-perola-cor-rustic-p-802916227.html?index=vr-prod-poc-madeira-listings-best-seller-desc&seller=17012 | C26: Conjunto Sala de Jantar Madesa Luana Mesa Tampo de Madeira com 4 Cadeiras Rustic/Sintético Bege | D26: WEB - MADEIRA | E26: 659.97 | F26: 49.9 | G26: 7 | H26: =IF(SUMIFS(Negociados!C:C,Negociados!B:B,E26,Negociados!A:A,A25,Negociados!D:D,"<="&$E$1,Negociados!E:E,">="&$E$1),SUMIFS(Negociados!C:C,Negociados!B:B,E26,Negociados!A:A,A25,Negociados!D:D,"<="&$E$1,Negociados!E:E,">="&$E$1),19%) -> 0.19
A27: MDJA0400885ZFLH | B27: https://www.madeiramadeira.com.br/conjunto-sala-de-jantar-madesa-luana-mesa-tampo-de-madeira-com-4-cadeiras-rustic-floral-hibiscos-cor-385866111.html | C27: Conjunto Sala de Jantar Madesa Luana Mesa Tampo de Madeira com 4 Cadeiras - Rustic/Floral Hibiscos Rustic/Floral Hibiscos | D27: WEB - MADEIRA | E27: 539.97 | F27: 49.9 | G27: 7 | H27: =IF(SUMIFS(Negociados!C:C,Negociados!B:B,E27,Negociados!A:A,A26,Negociados!D:D,"<="&$E$1,Negociados!E:E,">="&$E$1),SUMIFS(Negociados!C:C,Negociados!B:B,E27,Negociados!A:A,A26,Negociados!D:D,"<="&$E$1,Negociados!E:E,">="&$E$1),19%) -> 0.19
A28: MDJA0400885ZFBM | B28: https://www.madeiramadeira.com.br/conjunto-sala-de-jantar-madesa-luana-mesa-tampo-de-madeira-com-4-cadeiras-rustic-bege-marrom-cor-rus-220538477.html?index=vr-prod-poc-madeira-listings-best-seller-desc&seller=17012 | C28: Conjunto Sala de Jantar Madesa Luana Mesa Tampo de Madeira com 4 Cadeiras - Rustic/Bege Marrom Rustic/Bege Marrom | D28: WEB - MADEIRA | E28: - | F28: - | G28: - | H28: =IF(SUMIFS(Negociados!C:C,Negociados!B:B,E28,Negociados!A:A,A27,Negociados!D:D,"<="&$E$1,Negociados!E:E,">="&$E$1),SUMIFS(Negociados!C:C,Negociados!B:B,E28,Negociados!A:A,A27,Negociados!D:D,"<="&$E$1,Negociados!E:E,">="&$E$1),19%) -> 0.19
A29: MDJA0200015ZPT | B29: https://www.madeiramadeira.com.br/conjunto-sala-de-jantar-madesa-gabi-mesa-tampo-de-madeira-com-2-cadeiras-rustic-preto-sintetico-pret-587278186.html?index=vr-prod-poc-madeira-listings-best-seller-desc&seller=17012 | C29: Conjunto Sala de Jantar Madesa Gabi Mesa Tampo de Madeira com 2 Cadeiras - Rustic/Preto/Sintético Preto Rustic/Preto/Sintético Preto | D29: WEB - MADEIRA | E29: 1889.97 | F29: Grátis | G29: 10 | H29: =IF(SUMIFS(Negociados!C:C,Negociados!B:B,E29,Negociados!A:A,A28,Negociados!D:D,"<="&$E$1,Negociados!E:E,">="&$E$1),SUMIFS(Negociados!C:C,Negociados!B:B,E29,Negociados!A:A,A28,Negociados!D:D,"<="&$E$1,Negociados!E:E,">="&$E$1),19%) -> 0.19
A30: MDJA0200015ZPER | B30: https://www.madeiramadeira.com.br/conjunto-sala-de-jantar-madesa-gabi-mesa-tampo-de-madeira-com-2-cadeiras-rustic-crema-perola-cor-rus-945103759.html?index=prod-poc-madeira | C30: Conjunto Sala de Jantar Madesa Gabi Mesa Tampo de Madeira com 2 Cadeiras - Rustic/Crema/Pérola Rustic/Crema/Pérola | D30: WEB - MADEIRA | E30: 1049.97 | F30: Grátis | G30: 7 | H30: =IF(SUMIFS(Negociados!C:C,Negociados!B:B,E30,Negociados!A:A,A29,Negociados!D:D,"<="&$E$1,Negociados!E:E,">="&$E$1),SUMIFS(Negociados!C:C,Negociados!B:B,E30,Negociados!A:A,A29,Negociados!D:D,"<="&$E$1,Negociados!E:E,">="&$E$1),19%) -> 0.19
A31: GRNC2400053B | B31: https://www.madeiramadeira.com.br/armario-de-cozinha-completa-suspenso-240cm-cinza-758111417.html | C31: Armário de Cozinha Completa Suspenso 240cm Cinza Nice Madesa 05 | D31: WEB - MADEIRA | E31: 1889.97 | F31: Grátis | G31: 7 | H31: =IF(SUMIFS(Negociados!C:C,Negociados!B:B,E31,Negociados!A:A,A30,Negociados!D:D,"<="&$E$1,Negociados!E:E,">="&$E$1),SUMIFS(Negociados!C:C,Negociados!B:B,E31,Negociados!A:A,A30,Negociados!D:D,"<="&$E$1,Negociados!E:E,">="&$E$1),19%) -> 0.19
A32: GRNC2400043B | B32: https://www.madeiramadeira.com.br/armario-de-cozinha-completa-suspenso-240cm-cinza-663936177.html?index=vr-prod-poc-madeira-listings-best-seller-desc&seller=17012 | C32: Armário de Cozinha Completa Suspenso 240cm Cinza Nice Madesa 04 Cinza | D32: WEB - MADEIRA | H32: =IF(SUMIFS(Negociados!C:C,Negociados!B:B,E32,Negociados!A:A,A31,Negociados!D:D,"<="&$E$1,Negociados!E:E,">="&$E$1),SUMIFS(Negociados!C:C,Negociados!B:B,E32,Negociados!A:A,A31,Negociados!D:D,"<="&$E$1,Negociados!E:E,">="&$E$1),19%) -> 0.19
A33: GRNC3200063B | B33: https://www.madeiramadeira.com.br/armario-de-cozinha-completa-320cm-cinza-nice-madesa-06-cinza-741921112.html?index=vr-prod-poc-madeira-listings-best-seller-desc&seller=17012 | C33: Armário de Cozinha Completa 320cm Cinza Nice Madesa 06 | D33: WEB - MADEIRA | H33: =IF(SUMIFS(Negociados!C:C,Negociados!B:B,E33,Negociados!A:A,A32,Negociados!D:D,"<="&$E$1,Negociados!E:E,">="&$E$1),SUMIFS(Negociados!C:C,Negociados!B:B,E33,Negociados!A:A,A32,Negociados!D:D,"<="&$E$1,Negociados!E:E,">="&$E$1),19%) -> 0.19
A34: GRNC3000093B | B34: https://www.madeiramadeira.com.br/armario-de-cozinha-completa-300cm-cinza-nice-madesa-09-cinza-305948976.html?index=vr-prod-poc-madeira-listings-best-seller-desc&seller=17012 | C34: Armário de Cozinha Completa 300cm Cinza Nice Madesa 09 Cinza | D34: WEB - MADEIRA | H34: =IF(SUMIFS(Negociados!C:C,Negociados!B:B,E34,Negociados!A:A,A33,Negociados!D:D,"<="&$E$1,Negociados!E:E,">="&$E$1),SUMIFS(Negociados!C:C,Negociados!B:B,E34,Negociados!A:A,A33,Negociados!D:D,"<="&$E$1,Negociados!E:E,">="&$E$1),19%) -> 0.19
A35: GRNC1200013B | B35: https://www.madeiramadeira.com.br/armario-de-cozinha-compacta-120cm-cinza-nice-01-cinza-355744278.html?index=vr-prod-poc-madeira-listings-best-seller-desc&seller=17012 | C35: Armário de Cozinha Compacta 120cm Cinza Nice Madesa 01 Cinza | D35: WEB - MADEIRA | H35: =IF(SUMIFS(Negociados!C:C,Negociados!B:B,E35,Negociados!A:A,A34,Negociados!D:D,"<="&$E$1,Negociados!E:E,">="&$E$1),SUMIFS(Negociados!C:C,Negociados!B:B,E35,Negociados!A:A,A34,Negociados!D:D,"<="&$E$1,Negociados!E:E,">="&$E$1),19%) -> 0.19
A36: 1082093E | B36: https://www.madeiramadeira.com.br/guarda-roupa-casal-madesa-napoli-3-portas-de-correr-com-espelho-branco-cor-branco-384676114.html?index=prod-poc-madeira | C36: Guarda-Roupa Casal Madesa Napoli 3 Portas de Correr com Espelho - Branco | D36: WEB - MADEIRA | H36: =IF(SUMIFS(Negociados!C:C,Negociados!B:B,E36,Negociados!A:A,A35,Negociados!D:D,"<="&$E$1,Negociados!E:E,">="&$E$1),SUMIFS(Negociados!C:C,Negociados!B:B,E36,Negociados!A:A,A35,Negociados!D:D,"<="&$E$1,Negociados!E:E,">="&$E$1),19%) -> 0.19
A37: 104409A | B37: https://www.madeiramadeira.com.br/guarda-roupas-luke-branco-2-portas-de-correr-madesa-823701488.html?index=prod-poc-madeira&seller=17012 | C37: Guarda-Roupa Solteiro Madesa Luke 2 Portas de Correr de Madeira Branco | D37: WEB - MADEIRA | H37: =IF(SUMIFS(Negociados!C:C,Negociados!B:B,E37,Negociados!A:A,A36,Negociados!D:D,"<="&$E$1,Negociados!E:E,">="&$E$1),SUMIFS(Negociados!C:C,Negociados!B:B,E37,Negociados!A:A,A36,Negociados!D:D,"<="&$E$1,Negociados!E:E,">="&$E$1),19%) -> 0.19
A38: GRAG1200027K | B38: https://www.madeiramadeira.com.br/cozinha-compacta-madesa-agata-120002-com-armario-e-balcao-sem-tampo-e-pia-rustic-preto-cor-rustic-745393260.html?index=prod-poc-madeira&seller=17012 | C38: Cozinha Compacta Madesa Agata 120002 com Armário e Balcão (Sem Tampo e Pia) - Rustic/Preto Rustic/Preto | D38: WEB - MADEIRA | H38: =IF(SUMIFS(Negociados!C:C,Negociados!B:B,E38,Negociados!A:A,A37,Negociados!D:D,"<="&$E$1,Negociados!E:E,">="&$E$1),SUMIFS(Negociados!C:C,Negociados!B:B,E38,Negociados!A:A,A37,Negociados!D:D,"<="&$E$1,Negociados!E:E,">="&$E$1),19%) -> 0.19
A39: MDJA0601337GSIM | B39: https://www.madeiramadeira.com.br/conjunto-sala-de-jantar-mesa-tampo-de-vidro-6-cadeiras-rust-905165098.html?index=prod-poc-madeira&seller=17012 | C39: Conjunto Sala de Jantar Mesa Tampo de Vidro 6 Cadeiras Rustic/Crema/Imperial Stéfani Madesa Rustic/Crema/Imperial | D39: WEB - MADEIRA | H39: =IF(SUMIFS(Negociados!C:C,Negociados!B:B,E39,Negociados!A:A,A38,Negociados!D:D,"<="&$E$1,Negociados!E:E,">="&$E$1),SUMIFS(Negociados!C:C,Negociados!B:B,E39,Negociados!A:A,A38,Negociados!D:D,"<="&$E$1,Negociados!E:E,">="&$E$1),19%) -> 0.19
A40: G200807K8N | B40: https://www.madeiramadeira.com.br/cozinha-compacta-madesa-reims-com-balcao-5-portas-3-gavetas-preto-cor-preto-994226401.html?index=prod-poc-madeira&seller=17012 | C40: Cozinha Compacta Madesa Reims com Balcão - 5 Portas 3 Gavetas Preto | D40: WEB - MADEIRA | H40: =IF(SUMIFS(Negociados!C:C,Negociados!B:B,E40,Negociados!A:A,A39,Negociados!D:D,"<="&$E$1,Negociados!E:E,">="&$E$1),SUMIFS(Negociados!C:C,Negociados!B:B,E40,Negociados!A:A,A39,Negociados!D:D,"<="&$E$1,Negociados!E:E,">="&$E$1),19%) -> 0.19
A41: GCNC4050033B | B41: https://www.madeiramadeira.com.br/armario-de-cozinha-completa-de-canto-suspenso-405cm-nice-madesa-03-cinza-703310513.html?index=prod-poc-madeira&seller=17012 | C41: Armário de Cozinha Completa de Canto Suspenso 405cm Cinza Nice Madesa 03 Cinza | D41: WEB - MADEIRA | H41: =IF(SUMIFS(Negociados!C:C,Negociados!B:B,E41,Negociados!A:A,A40,Negociados!D:D,"<="&$E$1,Negociados!E:E,">="&$E$1),SUMIFS(Negociados!C:C,Negociados!B:B,E41,Negociados!A:A,A40,Negociados!D:D,"<="&$E$1,Negociados!E:E,">="&$E$1),19%) -> 0.19
...

Sheet SHOPEE
E1: 45950
A2: Cód. Madesa | B2: LINK | C2: Descrição | D2: Canal | E2: Preço | F2: FRETE | G2: PRAZO | H2: Comissão
